File: XRD/data/nbn_mgo.csv
[Measurement conditions]
Sample identification,
Comment - 1,"Configuration=FACTORY CONFIGURATION, Owner=User-1, Creation date=2008/9/16 ?? 08:01:59"
Comment - 2,"Goniometer=PW3050/65 (Theta/2Theta); Minimum step size 2Theta:0.0001; Minimum step size Omega:0.0001"
Comment - 3,"Sample stage=MRD Cradle; Minimum step size Phi:0.01; Minimum step size Psi:0.01; Minimum step size X:0.01; Minimum step size Y:0.01; Minimum step size Z:0.001"
Comment - 4,"Diffractometer system=XPERT-PRO"
Comment - 5,"Measurement program=2Theta scan for GIAD, Owner=joe, Creation date=2019/6/22 ?? 04:59:21"
Anode material,Cu
K-Alpha1 wavelength,1.5405980
K-Alpha2 wavelength,1.5444260
Ratio K-Alpha2/K-Alpha1,0.500
Divergence slit,Fixed,10.00mm
Receiving slit,0.10
Monochromator used,NO
Generator voltage, 45
Tube current, 30
File date and time,10/днды/2023 03:21
Unit cell,
h k l, 0 0 0
Scan axis,2Theta-Omega
Scan range,20.00000,90.00500
Scan step size,0.0150000
Omega offset,-0.22720
No. of points, 4667
Scan type,CONTINUOUS
Phi,0.00
Psi,0.13
X,0.00
Y,0.00
Z,8.159
Time per step,2.00
[Scan points]
Angle,Intensity
20.00750,17048.0
20.06750,17403.0
20.12750,17431.0
20.18750,17575.0
20.24750,17594.0
20.30750,17757.0
20.36750,17881.0
20.42750,17871.0
20.48750,17715.0
20.54750,18286.0
20.60750,18370.0
20.66750,18195.0
20.72750,18664.0
20.78750,18723.0
20.84750,19352.0
20.90750,19006.0
20.96750,19076.0
21.02750,18759.0
21.08750,18973.0
21.14750,19137.0
21.20750,19240.0
21.26750,19637.0
21.32750,19831.0
21.38750,19669.0
21.44750,19868.0
21.50750,19921.0
21.56750,20030.0
21.62750,19675.0
21.68750,19856.0
21.74750,20090.0
21.80750,20035.0
21.86750,20102.0
21.92750,20288.0
21.98750,20460.0
22.04750,20352.0
22.10750,20476.0
22.16750,20591.0
22.22750,20865.0
22.28750,20929.0
22.34750,20479.0
22.40750,21117.0
22.46750,20872.0
22.52750,21053.0
22.58750,21027.0
22.64750,21232.0
22.70750,21064.0
22.76750,21325.0
22.82750,21586.0
22.88750,21524.0
22.94750,21785.0
23.00750,21509.0
23.06750,21685.0
23.12750,21658.0
23.18750,21470.0
23.24750,21433.0
23.30750,21472.0
23.36750,21479.0
23.42750,21566.0
23.48750,21877.0
23.54750,21351.0
23.60750,21905.0
23.66750,21320.0
23.72750,21664.0
23.78750,22043.0
23.84750,21578.0
23.90750,21475.0
23.96750,22025.0
24.02750,21912.0
24.08750,21707.0
24.14750,21666.0
24.20750,22247.0
24.26750,22285.0
24.32750,22079.0
24.38750,22033.0
24.44750,22475.0
24.50750,22289.0
24.56750,22538.0
24.62750,22094.0
24.68750,22469.0
24.74750,22376.0
24.80750,22281.0
24.86750,22871.0
24.92750,22560.0
24.98750,22608.0
25.04750,22593.0
25.10750,22311.0
25.16750,22483.0
25.22750,22152.0
25.28750,22549.0
25.34750,22361.0
25.40750,22612.0
25.46750,22672.0
25.52750,22796.0
25.58750,22919.0
25.64750,22861.0
25.70750,22673.0
25.76750,22507.0
25.82750,22452.0
25.88750,23029.0
25.94750,22683.0
26.00750,23005.0
26.06750,22750.0
26.12750,23041.0
26.18750,22603.0
26.24750,22744.0
26.30750,22597.0
26.36750,22560.0
26.42750,22568.0
26.48750,22125.0
26.54750,22518.0
26.60750,22038.0
26.66750,22024.0
26.72750,22082.0
26.78750,21752.0
26.84750,22455.0
26.90750,21898.0
26.96750,22188.0
27.02750,21921.0
27.08750,21708.0
27.14750,21466.0
27.20750,21346.0
27.26750,21303.0
27.32750,21039.0
27.38750,21433.0
27.44750,21051.0
27.50750,20557.0
27.56750,20553.0
27.62750,20198.0
27.68750,20221.0
27.74750,20130.0
27.80750,19935.0
27.86750,19992.0
27.92750,20006.0
27.98750,19802.0
28.04750,19599.0
28.10750,19466.0
28.16750,19398.0
28.22750,19513.0
28.28750,19616.0
28.34750,19626.0
28.40750,19959.0
28.46750,19418.0
28.52750,19081.0
28.58750,18504.0
28.64750,18652.0
28.70750,17981.0
28.76750,17871.0
28.82750,17927.0
28.88750,17663.0
28.94750,17428.0
29.00750,17056.0
29.06750,17232.0
29.12750,17248.0
29.18750,17651.0
29.24750,18548.0
29.30750,19226.0
29.36750,19213.0
29.42750,18847.0
29.48750,18337.0
29.54750,17798.0
29.60750,16877.0
29.66750,16398.0
29.72750,16111.0
29.78750,15621.0
29.84750,15099.0
29.90750,15025.0
29.96750,14773.0
30.02750,14730.0
30.08750,14935.0
30.14750,16118.0
30.20750,18297.0
30.26750,20468.0
30.32750,21852.0
30.38750,21262.0
30.44750,19291.0
30.50750,17700.0
30.56750,15069.0
30.62750,13314.0
30.68750,12662.0
30.74750,12345.0
30.80750,11861.0
30.86750,11917.0
30.92750,11621.0
30.98750,11510.0
31.04750,11403.0
31.10750,11133.0
31.16750,11256.0
31.22750,10910.0
31.28750,11155.0
31.34750,10828.0
31.40750,10619.0
31.46750,10381.0
31.52750,10021.0
31.58750,9892.0
31.64750,9859.0
31.70750,9504.0
31.76750,9426.0
31.82750,9341.0
31.88750,9083.0
31.94750,8836.0
32.00750,8487.0
32.06750,8766.0
32.12750,8629.0
32.18750,8531.0
32.24750,8580.0
32.30750,8328.0
32.36750,8190.0
32.42750,8016.0
32.48750,7890.0
32.54750,7697.0
32.60750,7869.0
32.66750,7621.0
32.72750,7703.0
32.78750,7427.0
32.84750,7301.0
32.90750,7157.0
32.96750,6997.0
33.02750,6930.0
33.08750,6812.0
33.14750,6807.0
33.20750,6875.0
33.26750,6722.0
33.32750,6818.0
33.38750,6684.0
33.44750,6809.0
33.50750,6695.0
33.56750,6590.0
33.62750,6599.0
33.68750,6508.0
33.74750,6487.0
33.80750,6432.0
33.86750,6363.0
33.92750,6257.0
33.98750,6320.0
34.04750,6144.0
34.10750,6188.0
34.16750,6208.0
34.22750,6809.0
34.28750,7975.0
34.34750,9520.0
34.40750,11289.0
34.46750,11862.0
34.52750,11564.0
34.58750,10355.0
34.64750,9200.0
34.70750,7780.0
34.76750,7052.0
34.82750,6659.0
34.88750,6770.0
34.94750,7253.0
35.00750,7150.0
35.06750,6960.0
35.12750,6456.0
35.18750,6153.0
35.24750,6097.0
35.30750,7342.0
35.36750,9166.0
35.42750,12048.0
35.48750,14544.0
35.54750,15063.0
35.60750,14042.0
35.66750,12627.0
35.72750,10333.0
35.78750,7802.0
35.84750,6181.0
35.90750,5528.0
35.96750,5256.0
36.02750,5216.0
36.08750,5415.0
36.14750,5183.0
36.20750,5257.0
36.26750,4715.0
36.32750,4501.0
36.38750,4360.0
36.44750,4359.0
36.50750,4130.0
36.56750,4179.0
36.62750,4313.0
36.68750,4355.0
36.74750,4338.0
36.80750,4411.0
36.86750,4190.0
36.92750,4264.0
36.98750,4231.0
37.04750,4051.0
37.10750,4116.0
37.16750,3933.0
37.22750,3877.0
37.28750,3895.0
37.34750,3887.0
37.40750,3748.0
37.46750,3703.0
37.52750,3680.0
37.58750,3598.0
37.64750,3663.0
37.70750,3771.0
37.76750,3797.0
37.82750,3735.0
37.88750,3689.0
37.94750,3799.0
38.00750,3759.0
38.06750,3774.0
38.12750,3916.0
38.18750,4295.0
38.24750,4818.0
38.30750,5547.0
38.36750,6968.0
38.42750,10728.0
38.48750,20388.0
38.54750,33372.0
38.60750,49925.0
38.66750,59771.0
38.72750,62945.0
38.78750,57767.0
38.84750,48155.0
38.90750,35096.0
38.96750,22807.0
39.02750,14420.0
39.08750,8677.0
39.14750,6729.0
39.20750,6308.0
39.26750,6212.0
39.32750,6210.0
39.38750,6184.0
39.44750,6422.0
39.50750,6571.0
39.56750,6567.0
39.62750,6789.0
39.68750,6688.0
39.74750,6956.0
39.80750,6980.0
39.86750,7079.0
39.92750,7267.0
39.98750,7465.0
40.04750,8042.0
40.10750,8785.0
40.16750,9631.0
40.22750,11820.0
40.28750,14550.0
40.34750,18972.0
40.40750,26159.0
40.46750,37903.0
40.52750,55284.0
40.58750,80711.0
40.64750,111533.0
40.70750,143482.0
40.76750,173577.0
40.82750,195958.0
40.88750,208353.0
40.94750,203521.0
41.00750,185295.0
41.06750,161887.0
41.12750,135801.0
41.18750,107769.0
41.24750,89760.0
41.30750,80914.0
41.36750,83811.0
41.42750,96673.0
41.48750,114485.0
41.54750,132364.0
41.60750,147339.0
41.66750,155229.0
41.72750,163405.0
41.78750,163881.0
41.84750,162624.0
41.90750,161475.0
41.96750,160917.0
42.02750,162409.0
42.08750,163922.0
42.14750,161572.0
42.20750,165431.0
42.26750,167911.0
42.32750,175532.0
42.38750,185506.0
42.44750,198592.0
42.50750,228093.0
42.56750,296812.0
42.62750,500655.0
42.68750,1168515.0
42.74750,3231177.0
42.80750,6796731.0
42.86750,11917687.0
42.92750,18434064.0
42.98750,23445942.0
43.04750,26537670.0
43.10750,25110044.0
43.16750,21534996.0
43.22750,16584687.0
43.28750,11239148.0
43.34750,6847438.0
43.40750,3471426.0
43.46750,1546886.0
43.52750,597267.0
43.58750,309730.0
43.64750,236890.0
43.70750,203600.0
43.76750,185465.0
43.82750,170425.0
43.88750,158778.0
43.94750,148034.0
44.00750,138369.0
44.06750,132853.0
44.12750,127351.0
44.18750,120596.0
44.24750,116598.0
44.30750,112973.0
44.36750,107580.0
44.42750,104304.0
44.48750,101498.0
44.54750,98907.0
44.60750,95986.0
44.66750,94021.0
44.72750,92238.0
44.78750,90878.0
44.84750,89723.0
44.90750,88498.0
44.96750,85060.0
45.02750,82332.0
45.08750,81149.0
45.14750,79484.0
45.20750,78439.0
45.26750,77249.0
45.32750,75737.0
45.38750,74285.0
45.44750,72167.0
45.50750,70721.0
45.56750,69198.0
45.62750,69465.0
45.68750,66856.0
45.74750,65764.0
45.80750,63583.0
45.86750,63521.0
45.92750,63135.0
45.98750,61534.0
46.04750,60127.0
46.10750,58997.0
46.16750,58089.0
46.22750,58090.0
46.28750,58657.0
46.34750,58995.0
46.40750,59825.0
46.46750,59118.0
46.52750,57944.0
46.58750,57668.0
46.64750,56040.0
46.70750,56138.0
46.76750,55936.0
46.82750,55861.0
46.88750,56735.0
46.94750,57347.0
47.00750,58193.0
47.06750,59137.0
47.12750,57359.0
47.18750,55283.0
47.24750,52266.0
47.30750,50311.0
47.36750,48633.0
47.42750,46563.0
47.48750,45331.0
47.54750,42860.0
47.60750,42193.0
47.66750,42641.0
47.72750,41169.0
47.78750,41080.0
47.84750,40556.0
47.90750,39882.0
47.96750,39342.0
48.02750,38622.0
48.08750,37780.0
48.14750,36698.0
48.20750,36525.0
48.26750,34872.0
48.32750,34590.0
48.38750,33727.0
48.44750,34132.0
48.50750,34619.0
48.56750,33451.0
48.62750,32857.0
48.68750,32351.0
48.74750,31688.0
48.80750,31178.0
48.86750,30785.0
48.92750,31287.0
48.98750,30787.0
49.04750,30415.0
49.10750,30093.0
49.16750,30113.0
49.22750,29907.0
49.28750,28760.0
49.34750,28879.0
49.40750,28425.0
49.46750,27822.0
49.52750,28138.0
49.58750,27473.0
49.64750,27791.0
49.70750,26879.0
49.76750,25680.0
49.82750,25797.0
49.88750,25957.0
49.94750,25252.0
50.00750,25073.0
50.06750,24741.0
50.12750,24438.0
50.18750,23814.0
50.24750,24088.0
50.30750,23864.0
50.36750,23603.0
50.42750,23069.0
50.48750,23283.0
50.54750,22770.0
50.60750,22588.0
50.66750,21115.0
50.72750,20777.0
50.78750,21434.0
50.84750,20292.0
50.90750,20354.0
50.96750,20447.0
51.02750,19396.0
51.08750,19684.0
51.14750,19325.0
51.20750,19013.0
51.26750,18933.0
51.32750,18571.0
51.38750,18553.0
51.44750,18148.0
51.50750,17970.0
51.56750,18070.0
51.62750,17751.0
51.68750,17002.0
51.74750,16692.0
51.80750,16111.0
51.86750,16272.0
51.92750,16549.0
51.98750,16251.0
52.04750,15933.0
52.10750,15779.0
52.16750,15058.0
52.22750,15146.0
52.28750,15441.0
52.34750,14885.0
52.40750,15053.0
52.46750,14728.0
52.52750,14655.0
52.58750,14223.0
52.64750,13996.0
52.70750,13784.0
52.76750,13483.0
52.82750,13317.0
52.88750,13065.0
52.94750,13188.0
53.00750,12513.0
53.06750,12655.0
53.12750,12208.0
53.18750,12351.0
53.24750,11951.0
53.30750,11858.0
53.36750,11610.0
53.42750,11450.0
53.48750,11413.0
53.54750,11642.0
53.60750,11530.0
53.66750,11286.0
53.72750,11227.0
53.78750,11473.0
53.84750,11652.0
53.90750,12268.0
53.96750,12513.0
54.02750,12401.0
54.08750,12608.0
54.14750,12202.0
54.20750,11795.0
54.26750,11284.0
54.32750,10659.0
54.38750,10402.0
54.44750,9612.0
54.50750,9622.0
54.56750,9114.0
54.62750,9316.0
54.68750,9142.0
54.74750,9461.0
54.80750,9205.0
54.86750,9148.0
54.92750,9189.0
54.98750,8806.0
55.04750,8728.0
55.10750,8292.0
55.16750,8062.0
55.22750,7875.0
55.28750,7744.0
55.34750,7678.0
55.40750,7562.0
55.46750,7629.0
55.52750,7631.0
55.58750,7647.0
55.64750,7277.0
55.70750,7042.0
55.76750,7226.0
55.82750,7111.0
55.88750,7138.0
55.94750,7071.0
56.00750,6771.0
56.06750,6384.0
56.12750,6469.0
56.18750,6469.0
56.24750,6545.0
56.30750,6191.0
56.36750,6517.0
56.42750,6230.0
56.48750,5915.0
56.54750,6029.0
56.60750,6065.0
56.66750,5677.0
56.72750,5884.0
56.78750,5568.0
56.84750,5621.0
56.90750,5764.0
56.96750,5307.0
57.02750,5405.0
57.08750,5450.0
57.14750,5469.0
57.20750,5479.0
57.26750,5402.0
57.32750,5215.0
57.38750,5028.0
57.44750,5001.0
57.50750,5110.0
57.56750,4922.0
57.62750,4933.0
57.68750,4938.0
57.74750,4804.0
57.80750,4905.0
57.86750,4790.0
57.92750,4624.0
57.98750,4772.0
58.04750,4563.0
58.10750,4573.0
58.16750,4402.0
58.22750,4405.0
58.28750,4313.0
58.34750,4381.0
58.40750,4298.0
58.46750,4399.0
58.52750,4411.0
58.58750,4542.0
58.64750,4261.0
58.70750,4188.0
58.76750,4065.0
58.82750,4078.0
58.88750,3929.0
58.94750,3955.0
59.00750,3783.0
59.06750,3884.0
59.12750,3821.0
59.18750,3729.0
59.24750,3751.0
59.30750,3610.0
59.36750,3700.0
59.42750,3524.0
59.48750,3617.0
59.54750,3691.0
59.60750,3612.0
59.66750,3717.0
59.72750,4131.0
59.78750,4388.0
59.84750,4646.0
59.90750,5559.0
59.96750,5731.0
60.02750,6510.0
60.08750,6149.0
60.14750,5834.0
60.20750,5206.0
60.26750,4691.0
60.32750,4183.0
60.38750,3597.0
60.44750,3424.0
60.50750,3466.0
60.56750,3328.0
60.62750,3578.0
60.68750,3488.0
60.74750,3332.0
60.80750,3414.0
60.86750,3280.0
60.92750,3219.0
60.98750,3283.0
61.04750,3235.0
61.10750,3247.0
61.16750,3103.0
61.22750,2903.0
61.28750,2960.0
61.34750,2820.0
61.40750,2793.0
61.46750,2788.0
61.52750,2766.0
61.58750,2671.0
61.64750,2687.0
61.70750,2727.0
61.76750,2568.0
61.82750,2564.0
61.88750,2680.0
61.94750,2577.0
62.00750,2546.0
62.06750,2577.0
62.12750,2533.0
62.18750,2580.0
62.24750,2459.0
62.30750,2465.0
62.36750,2381.0
62.42750,2451.0
62.48750,2430.0
62.54750,2383.0
62.60750,2393.0
62.66750,2477.0
62.72750,2454.0
62.78750,2777.0
62.84750,3202.0
62.90750,3767.0
62.96750,4165.0
63.02750,4306.0
63.08750,3916.0
63.14750,3536.0
63.20750,3122.0
63.26750,2689.0
63.32750,2345.0
63.38750,2261.0
63.44750,2115.0
63.50750,2117.0
63.56750,1975.0
63.62750,2158.0
63.68750,2103.0
63.74750,1964.0
63.80750,2070.0
63.86750,1970.0
63.92750,2097.0
63.98750,2040.0
64.04750,1990.0
64.10750,2049.0
64.16750,2023.0
64.22750,1905.0
64.28750,1922.0
64.34750,2040.0
64.40750,1917.0
64.46750,1866.0
64.52750,1865.0
64.58750,1894.0
64.64750,1923.0
64.70750,1798.0
64.76750,1845.0
64.82750,1873.0
64.88750,1862.0
64.94750,1854.0
65.00750,1917.0
65.06750,1862.0
65.12750,1786.0
65.18750,1756.0
65.24750,1857.0
65.30750,1968.0
65.36750,1829.0
65.42750,1750.0
65.48750,1583.0
65.54750,1727.0
65.60750,1746.0
65.66750,1724.0
65.72750,1637.0
65.78750,1718.0
65.84750,1631.0
65.90750,1772.0
65.96750,1677.0
66.02750,1643.0
66.08750,1651.0
66.14750,1691.0
66.20750,1646.0
66.26750,1614.0
66.32750,1590.0
66.38750,1562.0
66.44750,1475.0
66.50750,1536.0
66.56750,1491.0
66.62750,1508.0
66.68750,1493.0
66.74750,1509.0
66.80750,1438.0
66.86750,1540.0
66.92750,1555.0
66.98750,1515.0
67.04750,1451.0
67.10750,1457.0
67.16750,1463.0
67.22750,1437.0
67.28750,1448.0
67.34750,1394.0
67.40750,1448.0
67.46750,1391.0
67.52750,1290.0
67.58750,1350.0
67.64750,1414.0
67.70750,1395.0
67.76750,1427.0
67.82750,1421.0
67.88750,1395.0
67.94750,1355.0
68.00750,1443.0
68.06750,1405.0
68.12750,1394.0
68.18750,1385.0
68.24750,1424.0
68.30750,1368.0
68.36750,1263.0
68.42750,1331.0
68.48750,1325.0
68.54750,1214.0
68.60750,1333.0
68.66750,1200.0
68.72750,1253.0
68.78750,1293.0
68.84750,1309.0
68.90750,1267.0
68.96750,1318.0
69.02750,1333.0
69.08750,1270.0
69.14750,1322.0
69.20750,1281.0
69.26750,1269.0
69.32750,1180.0
69.38750,1283.0
69.44750,1270.0
69.50750,1212.0
69.56750,1251.0
69.62750,1175.0
69.68750,1213.0
69.74750,1199.0
69.80750,1218.0
69.86750,1195.0
69.92750,1253.0
69.98750,1205.0
70.04750,1256.0
70.10750,1156.0
70.16750,1216.0
70.22750,1245.0
70.28750,1150.0
70.34750,1151.0
70.40750,1141.0
70.46750,1177.0
70.52750,1145.0
70.58750,1188.0
70.64750,1093.0
70.70750,1189.0
70.76750,1109.0
70.82750,1172.0
70.88750,1184.0
70.94750,1246.0
71.00750,1072.0
71.06750,1131.0
71.12750,1204.0
71.18750,1255.0
71.24750,1117.0
71.30750,1163.0
71.36750,1153.0
71.42750,1054.0
71.48750,1109.0
71.54750,1116.0
71.60750,1075.0
71.66750,1071.0
71.72750,1077.0
71.78750,1052.0
71.84750,1104.0
71.90750,1076.0
71.96750,1115.0
72.02750,1123.0
72.08750,1060.0
72.14750,1070.0
72.20750,1172.0
72.26750,1283.0
72.32750,1319.0
72.38750,1515.0
72.44750,1815.0
72.50750,2051.0
72.56750,2208.0
72.62750,2222.0
72.68750,1990.0
72.74750,1807.0
72.80750,1532.0
72.86750,1345.0
72.92750,1173.0
72.98750,1173.0
73.04750,1091.0
73.10750,1075.0
73.16750,1065.0
73.22750,1043.0
73.28750,986.0
73.34750,937.0
73.40750,1036.0
73.46750,1066.0
73.52750,1010.0
73.58750,1097.0
73.64750,1167.0
73.70750,1216.0
73.76750,1418.0
73.82750,1359.0
73.88750,1338.0
73.94750,1304.0
74.00750,1189.0
74.06750,1134.0
74.12750,1003.0
74.18750,996.0
74.24750,968.0
74.30750,902.0
74.36750,976.0
74.42750,937.0
74.48750,951.0
74.54750,967.0
74.60750,938.0
74.66750,944.0
74.72750,995.0
74.78750,1120.0
74.84750,1215.0
74.90750,1660.0
74.96750,2250.0
75.02750,2603.0
75.08750,2944.0
75.14750,2841.0
75.20750,2673.0
75.26750,2292.0
75.32750,1823.0
75.38750,1476.0
75.44750,1093.0
75.50750,1017.0
75.56750,1039.0
75.62750,996.0
75.68750,951.0
75.74750,973.0
75.80750,905.0
75.86750,889.0
75.92750,914.0
75.98750,908.0
76.04750,856.0
76.10750,927.0
76.16750,853.0
76.22750,979.0
76.28750,1001.0
76.34750,1001.0
76.40750,1000.0
76.46750,1032.0
76.52750,1043.0
76.58750,930.0
76.64750,992.0
76.70750,912.0
76.76750,886.0
76.82750,830.0
76.88750,801.0
76.94750,811.0
77.00750,821.0
77.06750,907.0
77.12750,768.0
77.18750,801.0
77.24750,804.0
77.30750,842.0
77.36750,797.0
77.42750,811.0
77.48750,837.0
77.54750,807.0
77.60750,805.0
77.66750,793.0
77.72750,735.0
77.78750,844.0
77.84750,844.0
77.90750,818.0
77.96750,796.0
78.02750,849.0
78.08750,795.0
78.14750,798.0
78.20750,794.0
78.26750,829.0
78.32750,790.0
78.38750,826.0
78.44750,754.0
78.50750,746.0
78.56750,729.0
78.62750,845.0
78.68750,773.0
78.74750,796.0
78.80750,793.0
78.86750,745.0
78.92750,798.0
78.98750,780.0
79.04750,751.0
79.10750,790.0
79.16750,804.0
79.22750,775.0
79.28750,747.0
79.34750,737.0
79.40750,775.0
79.46750,727.0
79.52750,732.0
79.58750,741.0
79.64750,745.0
79.70750,778.0
79.76750,757.0
79.82750,772.0
79.88750,795.0
79.94750,746.0
80.00750,759.0
80.06750,696.0
80.12750,681.0
80.18750,724.0
80.24750,729.0
80.30750,757.0
80.36750,743.0
80.42750,757.0
80.48750,710.0
80.54750,710.0
80.60750,716.0
80.66750,762.0
80.72750,707.0
80.78750,753.0
80.84750,674.0
80.90750,742.0
80.96750,735.0
81.02750,730.0
81.08750,724.0
81.14750,673.0
81.20750,715.0
81.26750,740.0
81.32750,683.0
81.38750,698.0
81.44750,746.0
81.50750,714.0
81.56750,694.0
81.62750,739.0
81.68750,716.0
81.74750,742.0
81.80750,771.0
81.86750,809.0
81.92750,920.0
81.98750,1025.0
82.04750,969.0
82.10750,971.0
82.16750,1017.0
82.22750,1040.0
82.28750,975.0
82.34750,1044.0
82.40750,1064.0
82.46750,1134.0
82.52750,1271.0
82.58750,1856.0
82.64750,3346.0
82.70750,5625.0
82.76750,8048.0
82.82750,10395.0
82.88750,11293.0
82.94750,10983.0
83.00750,9589.0
83.06750,7343.0
83.12750,5338.0
83.18750,3589.0
83.24750,2206.0
83.30750,1489.0
83.36750,1250.0
83.42750,1135.0
83.48750,1025.0
83.54750,1075.0
83.60750,926.0
83.66750,959.0
83.72750,881.0
83.78750,839.0
83.84750,871.0
83.90750,865.0
83.96750,892.0
84.02750,879.0
84.08750,861.0
84.14750,840.0
84.20750,854.0
84.26750,807.0
84.32750,831.0
84.38750,855.0
84.44750,899.0
84.50750,762.0
84.56750,856.0
84.62750,810.0
84.68750,801.0
84.74750,800.0
84.80750,842.0
84.86750,808.0
84.92750,820.0
84.98750,848.0
85.04750,809.0
85.10750,864.0
85.16750,793.0
85.22750,808.0
85.28750,845.0
85.34750,751.0
85.40750,793.0
85.46750,799.0
85.52750,823.0
85.58750,767.0
85.64750,789.0
85.70750,840.0
85.76750,768.0
85.82750,811.0
85.88750,743.0
85.94750,799.0
86.00750,768.0
86.06750,795.0
86.12750,806.0
86.18750,791.0
86.24750,764.0
86.30750,871.0
86.36750,772.0
86.42750,747.0
86.48750,806.0
86.54750,808.0
86.60750,758.0
86.66750,814.0
86.72750,747.0
86.78750,794.0
86.84750,840.0
86.90750,784.0
86.96750,832.0
87.02750,846.0
87.08750,880.0
87.14750,833.0
87.20750,969.0
87.26750,973.0
87.32750,1042.0
87.38750,1165.0
87.44750,1233.0
87.50750,1282.0
87.56750,1413.0
87.62750,1527.0
87.68750,1722.0
87.74750,1946.0
87.80750,2161.0
87.86750,2486.0
87.92750,2920.0
87.98750,3479.0
88.04750,3975.0
88.10750,4712.0
88.16750,5343.0
88.22750,6552.0
88.28750,6987.0
88.34750,7708.0
88.40750,8539.0
88.46750,8741.0
88.52750,8824.0
88.58750,8535.0
88.64750,8309.0
88.70750,7638.0
88.76750,6970.0
88.82750,6504.0
88.88750,5729.0
88.94750,5110.0
89.00750,4668.0
89.06750,4144.0
89.12750,3738.0
89.18750,3386.0
89.24750,2996.0
89.30750,2640.0
89.36750,2226.0
89.42750,1987.0
89.48750,1808.0
89.54750,1514.0
89.60750,1425.0
89.66750,1427.0
89.72750,1659.0
89.78750,2062.0
89.84750,2860.0
89.90750,4445.0
89.96750,6406.0
89.99750,7677.0